{"uuid": "6b8deea5-fcf7-424c-8a01-28d9a6c05749", "children": ["d5cf3a43-6d8c-4848-8419-0d6ee141a56e", "4287af98-76a6-4005-89fc-e0ee1ffbe833"], "befores": [{"name": "stop", "status": "passed", "start": 1612814777769, "stop": 1612814777769}], "afters": [{"name": "stop::fin", "status": "broken", "statusDetails": {"message": "urllib3.exceptions.MaxRetryError: HTTPConnectionPool(host='127.0.0.1', port=50455): Max retries exceeded with url: /session/5e452f64-3cc2-4f14-9abb-b55d61a20e23/elements (Caused by NewConnectionError('<urllib3.connection.HTTPConnection object at 0x0000027262510E80>: Failed to establish a new connection: [WinError 10061] Подключение не установлено, т.к. конечный компьютер отверг запрос на подключение'))\n", "trace": "  File \"c:\\users\\trofimov-a\\pycharmprojects\\python_testing\\env\\lib\\site-packages\\allure_commons\\_allure.py\", line 200, in __call__\n    return self._fixture_function(*args, **kwargs)\n  File \"C:\\Users\\trofimov-a\\PycharmProjects\\python_testing\\conftest.py\", line 46, in fin\n    fixture.session.ensure_logout()\n  File \"C:\\Users\\trofimov-a\\PycharmProjects\\python_testing\\fixture\\session.py\", line 25, in ensure_logout\n    if self.is_logged_in():\n  File \"C:\\Users\\trofimov-a\\PycharmProjects\\python_testing\\fixture\\session.py\", line 30, in is_logged_in\n    return len(wd.find_elements_by_link_text(\"Logout\")) > 0\n  File \"c:\\users\\trofimov-a\\pycharmprojects\\python_testing\\env\\lib\\site-packages\\selenium\\webdriver\\remote\\webdriver.py\", line 444, in find_elements_by_link_text\n    return self.find_elements(by=By.LINK_TEXT, value=text)\n  File \"c:\\users\\trofimov-a\\pycharmprojects\\python_testing\\env\\lib\\site-packages\\selenium\\webdriver\\remote\\webdriver.py\", line 1005, in find_elements\n    return self.execute(Command.FIND_ELEMENTS, {\n  File \"c:\\users\\trofimov-a\\pycharmprojects\\python_testing\\env\\lib\\site-packages\\selenium\\webdriver\\remote\\webdriver.py\", line 319, in execute\n    response = self.command_executor.execute(driver_command, params)\n  File \"c:\\users\\trofimov-a\\pycharmprojects\\python_testing\\env\\lib\\site-packages\\selenium\\webdriver\\remote\\remote_connection.py\", line 374, in execute\n    return self._request(command_info[0], url, body=data)\n  File \"c:\\users\\trofimov-a\\pycharmprojects\\python_testing\\env\\lib\\site-packages\\selenium\\webdriver\\remote\\remote_connection.py\", line 397, in _request\n    resp = self._conn.request(method, url, body=body, headers=headers)\n  File \"c:\\users\\trofimov-a\\pycharmprojects\\python_testing\\env\\lib\\site-packages\\urllib3\\request.py\", line 78, in request\n    return self.request_encode_body(\n  File \"c:\\users\\trofimov-a\\pycharmprojects\\python_testing\\env\\lib\\site-packages\\urllib3\\request.py\", line 170, in request_encode_body\n    return self.urlopen(method, url, **extra_kw)\n  File \"c:\\users\\trofimov-a\\pycharmprojects\\python_testing\\env\\lib\\site-packages\\urllib3\\poolmanager.py\", line 375, in urlopen\n    response = conn.urlopen(method, u.request_uri, **kw)\n  File \"c:\\users\\trofimov-a\\pycharmprojects\\python_testing\\env\\lib\\site-packages\\urllib3\\connectionpool.py\", line 783, in urlopen\n    return self.urlopen(\n  File \"c:\\users\\trofimov-a\\pycharmprojects\\python_testing\\env\\lib\\site-packages\\urllib3\\connectionpool.py\", line 783, in urlopen\n    return self.urlopen(\n  File \"c:\\users\\trofimov-a\\pycharmprojects\\python_testing\\env\\lib\\site-packages\\urllib3\\connectionpool.py\", line 783, in urlopen\n    return self.urlopen(\n  File \"c:\\users\\trofimov-a\\pycharmprojects\\python_testing\\env\\lib\\site-packages\\urllib3\\connectionpool.py\", line 755, in urlopen\n    retries = retries.increment(\n  File \"c:\\users\\trofimov-a\\pycharmprojects\\python_testing\\env\\lib\\site-packages\\urllib3\\util\\retry.py\", line 573, in increment\n    raise MaxRetryError(_pool, url, error or ResponseError(cause))\n"}, "start": 1612814823854, "stop": 1612814831893}], "start": 1612814777769, "stop": 1612814831893}